2025-07-06 09:34:31,435 - INFO  -Starting JIRA project fetching process...
2025-07-06 09:34:31,436 - INFO  -Connecting to MongoDB with URI: mongodb+srv://info:xlhQRSPwz0RwzmXD@cluster0.rmyui...
2025-07-06 09:34:31,622 - INFO  -Looking for user with ID: 68696f783ad17ea0c39cbc65
2025-07-06 09:34:32,046 - INFO  -Found user document with fields: ['_id', 'jira_email', 'jira_domain', 'jira_api_key']
2025-07-06 09:34:32,046 - INFO  -Initialized JIRA client with:
2025-07-06 09:34:32,046 - INFO  -  - Email: camaraderie_experts@outlook.com
2025-07-06 09:34:32,046 - INFO  -  - Domain: string
2025-07-06 09:34:32,046 - INFO  -  - API Key: ************************************************************************************************************************************************************************************************
2025-07-06 09:34:32,079 - INFO  -Starting to fetch all JIRA project details...
2025-07-06 09:34:32,079 - INFO  -Fetching projects from URL: https://string/rest/api/3/project/search
2025-07-06 09:34:32,079 - INFO  -Request parameters: {'startAt': 0, 'maxResults': 50}
2025-07-06 09:34:39,331 - ERROR  -Network connection error to JIRA: Cannot connect to host string:443 ssl:default [getaddrinfo failed]
2025-07-06 09:34:39,333 - INFO  -Backing off fetch_projects(...) for 1.3s (aiohttp.client_exceptions.ClientConnectorDNSError: Cannot connect to host string:443 ssl:default [getaddrinfo failed])
2025-07-06 09:34:40,609 - INFO  -Fetching projects from URL: https://string/rest/api/3/project/search
2025-07-06 09:34:40,609 - INFO  -Request parameters: {'startAt': 0, 'maxResults': 50}
2025-07-06 09:34:43,309 - ERROR  -Network connection error to JIRA: Cannot connect to host string:443 ssl:default [getaddrinfo failed]
2025-07-06 09:34:43,310 - INFO  -Backing off fetch_projects(...) for 1.4s (aiohttp.client_exceptions.ClientConnectorDNSError: Cannot connect to host string:443 ssl:default [getaddrinfo failed])
2025-07-06 09:34:44,683 - INFO  -Fetching projects from URL: https://string/rest/api/3/project/search
2025-07-06 09:34:44,683 - INFO  -Request parameters: {'startAt': 0, 'maxResults': 50}
2025-07-06 09:34:46,955 - ERROR  -Network connection error to JIRA: Cannot connect to host string:443 ssl:default [getaddrinfo failed]
2025-07-06 09:34:46,955 - INFO  -Backing off fetch_projects(...) for 6.6s (aiohttp.client_exceptions.ClientConnectorDNSError: Cannot connect to host string:443 ssl:default [getaddrinfo failed])
2025-07-06 09:34:53,615 - INFO  -Fetching projects from URL: https://string/rest/api/3/project/search
2025-07-06 09:34:53,615 - INFO  -Request parameters: {'startAt': 0, 'maxResults': 50}
2025-07-06 09:35:00,868 - ERROR  -Network connection error to JIRA: Cannot connect to host string:443 ssl:default [getaddrinfo failed]
2025-07-06 09:35:00,868 - INFO  -Backing off fetch_projects(...) for 16.0s (aiohttp.client_exceptions.ClientConnectorDNSError: Cannot connect to host string:443 ssl:default [getaddrinfo failed])
2025-07-06 09:35:16,838 - INFO  -Fetching projects from URL: https://string/rest/api/3/project/search
2025-07-06 09:35:16,838 - INFO  -Request parameters: {'startAt': 0, 'maxResults': 50}
2025-07-06 09:35:24,072 - ERROR  -Network connection error to JIRA: Cannot connect to host string:443 ssl:default [getaddrinfo failed]
2025-07-06 09:35:24,072 - ERROR  -Giving up fetch_projects(...) after 5 tries (aiohttp.client_exceptions.ClientConnectorDNSError: Cannot connect to host string:443 ssl:default [getaddrinfo failed])
2025-07-06 09:35:24,072 - CRITICAL  -Failed to connect to JIRA. Please check network connectivity and JIRA server status: Cannot connect to host string:443 ssl:default [getaddrinfo failed]
2025-07-06 09:35:24,072 - ERROR  -Main execution failed
Traceback (most recent call last):
  File "E:\PM -AI-TOOL\pm-ai-tool\.venv\Lib\site-packages\aiohttp\connector.py", line 1512, in _create_direct_connection
    hosts = await self._resolve_host(host, port, traces=traces)
            ^^^^^^^^^^^^^^^^^^^^^^^^^^^^^^^^^^^^^^^^^^^^^^^^^^^
  File "E:\PM -AI-TOOL\pm-ai-tool\.venv\Lib\site-packages\aiohttp\connector.py", line 1128, in _resolve_host
    return await asyncio.shield(resolved_host_task)
           ^^^^^^^^^^^^^^^^^^^^^^^^^^^^^^^^^^^^^^^^
  File "E:\PM -AI-TOOL\pm-ai-tool\.venv\Lib\site-packages\aiohttp\connector.py", line 1159, in _resolve_host_with_throttle
    addrs = await self._resolver.resolve(host, port, family=self._family)
            ^^^^^^^^^^^^^^^^^^^^^^^^^^^^^^^^^^^^^^^^^^^^^^^^^^^^^^^^^^^^^
  File "E:\PM -AI-TOOL\pm-ai-tool\.venv\Lib\site-packages\aiohttp\resolver.py", line 40, in resolve
    infos = await self._loop.getaddrinfo(
            ^^^^^^^^^^^^^^^^^^^^^^^^^^^^^
  File "C:\Users\tousi\AppData\Local\Programs\Python\Python311\Lib\asyncio\base_events.py", line 864, in getaddrinfo
    return await self.run_in_executor(
           ^^^^^^^^^^^^^^^^^^^^^^^^^^^
  File "C:\Users\tousi\AppData\Local\Programs\Python\Python311\Lib\concurrent\futures\thread.py", line 58, in run
    result = self.fn(*self.args, **self.kwargs)
             ^^^^^^^^^^^^^^^^^^^^^^^^^^^^^^^^^^
  File "C:\Users\tousi\AppData\Local\Programs\Python\Python311\Lib\socket.py", line 961, in getaddrinfo
    for res in _socket.getaddrinfo(host, port, family, type, proto, flags):
               ^^^^^^^^^^^^^^^^^^^^^^^^^^^^^^^^^^^^^^^^^^^^^^^^^^^^^^^^^^^
socket.gaierror: [Errno 11001] getaddrinfo failed

The above exception was the direct cause of the following exception:

Traceback (most recent call last):
  File "e:\PM -AI-TOOL\pm-ai-tool\src\ingestion\fetch_projects.py", line 238, in <module>
    project_data = asyncio.run(fetch_all_project_details("68696f783ad17ea0c39cbc65"))
                   ^^^^^^^^^^^^^^^^^^^^^^^^^^^^^^^^^^^^^^^^^^^^^^^^^^^^^^^^^^^^^^^^^^
  File "C:\Users\tousi\AppData\Local\Programs\Python\Python311\Lib\asyncio\runners.py", line 190, in run
    return runner.run(main)
           ^^^^^^^^^^^^^^^^
  File "C:\Users\tousi\AppData\Local\Programs\Python\Python311\Lib\asyncio\runners.py", line 118, in run
    return self._loop.run_until_complete(task)
           ^^^^^^^^^^^^^^^^^^^^^^^^^^^^^^^^^^^
  File "C:\Users\tousi\AppData\Local\Programs\Python\Python311\Lib\asyncio\base_events.py", line 650, in run_until_complete
    return future.result()
           ^^^^^^^^^^^^^^^
  File "e:\PM -AI-TOOL\pm-ai-tool\src\ingestion\fetch_projects.py", line 190, in fetch_all_project_details
    projects_data = await fetch_projects(page_start_at, page_max_results, base_url=base_url, auth=auth, headers=headers)
                    ^^^^^^^^^^^^^^^^^^^^^^^^^^^^^^^^^^^^^^^^^^^^^^^^^^^^^^^^^^^^^^^^^^^^^^^^^^^^^^^^^^^^^^^^^^^^^^^^^^^^
  File "E:\PM -AI-TOOL\pm-ai-tool\.venv\Lib\site-packages\backoff\_async.py", line 151, in retry
    ret = await target(*args, **kwargs)
          ^^^^^^^^^^^^^^^^^^^^^^^^^^^^^
  File "e:\PM -AI-TOOL\pm-ai-tool\src\ingestion\fetch_projects.py", line 78, in fetch_projects
    async with session.get(url, params=params) as response:
  File "E:\PM -AI-TOOL\pm-ai-tool\.venv\Lib\site-packages\aiohttp\client.py", line 1480, in __aenter__
    self._resp: _RetType = await self._coro
                           ^^^^^^^^^^^^^^^^
  File "E:\PM -AI-TOOL\pm-ai-tool\.venv\Lib\site-packages\aiohttp\client.py", line 768, in _request
    resp = await handler(req)
           ^^^^^^^^^^^^^^^^^^
  File "E:\PM -AI-TOOL\pm-ai-tool\.venv\Lib\site-packages\aiohttp\client.py", line 723, in _connect_and_send_request
    conn = await self._connector.connect(
           ^^^^^^^^^^^^^^^^^^^^^^^^^^^^^^
  File "E:\PM -AI-TOOL\pm-ai-tool\.venv\Lib\site-packages\aiohttp\connector.py", line 622, in connect
    proto = await self._create_connection(req, traces, timeout)
            ^^^^^^^^^^^^^^^^^^^^^^^^^^^^^^^^^^^^^^^^^^^^^^^^^^^
  File "E:\PM -AI-TOOL\pm-ai-tool\.venv\Lib\site-packages\aiohttp\connector.py", line 1189, in _create_connection
    _, proto = await self._create_direct_connection(req, traces, timeout)
               ^^^^^^^^^^^^^^^^^^^^^^^^^^^^^^^^^^^^^^^^^^^^^^^^^^^^^^^^^^
  File "E:\PM -AI-TOOL\pm-ai-tool\.venv\Lib\site-packages\aiohttp\connector.py", line 1518, in _create_direct_connection
    raise ClientConnectorDNSError(req.connection_key, exc) from exc
aiohttp.client_exceptions.ClientConnectorDNSError: Cannot connect to host string:443 ssl:default [getaddrinfo failed]
